Workbook

Sheet Front page
A2: Internal Audit report
A6: Auditor:
A8: Date:
A10: Company:
A12: Current audit cycle: | C12: Pre-audit

Sheet User Manual
C1: Explanation
A2: You can choose to use | B2: The tab "checklist full" with all clauses and controls | C2: Both collection have the same clauses and controls
A3: Or | B3: The separate tabs checklist claused and checklist annex | C3: The separate tabs, split the clauses and the annexes
B5: IMPORTANT REMARK | C5: Both sets ("full" vs the other 2) are NOT connected, you choose which set to complete
A7: Column | B7: Reference documents | C7: Put a link to the document names
C8: Hint: also add version nr and review date
B9: TO DO: | C9: add documents with links in the column next to the clause or annex like: policies, procedure, process documentation,.. Hint: add version nr
A11: Column | B11: Audit evidence | C11: Additional evidence, except
B12: TO DO: | C12: (if different, add links to additional docs & reports) Other, incl interviewed people, metadata, system records, … Hint: add evidence, time and data of check
A14: Column | B14: Audit remarks | C14: Additional comments to add if useful, eg explaining NC/nc/OFI
A16: Column | B16: Audit qualification | C16: You can enter (fixed choice of 5 options)
C17: (empty)
C18: TBC (to be checked)
C19: OK
C20: OFI (= opportunitfy for improvement)
C21: nc- (= minor non-conformity)
C22: NC+ (= major non-conformity)
C24: The sheet will automatically color the field as indicated
A26: Column | B26: Relevant processes | C26: You can use or rename the existing fields or add columns for additional departments you audit
A28: Column | B28: Outsources | C28: Fixed choice of Yes/No, to indicate a process is outsourced to a 3rd party
A30: At the end of the table | B30: Evaluation count

Sheet Essential Audit Data
A1: Topic | B1: Value | C1: Extra Info
A2: Current Stage of audit | B2: Audit types
A3: Previous Internal audit | B3: =NOW() -> 45946.42 | C3: yyyy-mm-dd
A4: Previous External audit | B4: =NOW() -> 45946.42 | C4: yyyy-mm-dd
A7: Did you check previous audit reports for…
A8: Number of previous OFI/nc-/NC+? | B8: No
A9: Status of previous OFI/nc-/NC+? | B9: No
A11: Essential ISMS data
A12: SoA date | B12: =NOW() -> 45946.42 | C12: yyyy-mm-dd
A13: SoA Version | B13: V.0
A14: SoA Document name | B14: <SoA document name> | C14: Add name and link to doc
A16: ISMS Review Cycle
A17: Last Management Review | B17: =NOW() -> 45946.42 | C17: yyyy-mm-dd
A18: Last evaluation of ISMS objectives | B18: =NOW() -> 45946.42 | C18: yyyy-mm-dd
A19: Last revision of documentation | B19: =NOW() -> 45946.42 | C19: yyyy-mm-dd
A20: Last revision of risk assessments | B20: =NOW() -> 45946.42 | C20: yyyy-mm-dd

Sheet Quick Overview Results
A1: Checklist Clauses | B1: Type | C1: Count
A2: =SUM(C2:C7) -> 55 | C2: ='Checklist Mgmt Clauses'!H96 -> 0
B3: TBC | C3: ='Checklist Mgmt Clauses'!H97 -> 1
B4: OK | C4: ='Checklist Mgmt Clauses'!H98 -> 49
B5: OFI | C5: ='Checklist Mgmt Clauses'!H99 -> 1
B6: nc- | C6: ='Checklist Mgmt Clauses'!H100 -> 2
B7: NC+ | C7: ='Checklist Mgmt Clauses'!H101 -> 2
A9: Checklist Annex | B9: Type | C9: Count
A10: =SUM(C10:C15) -> 93 | C10: ='Checklist Annex Controls'!I195 -> 0
B11: TBC | C11: ='Checklist Annex Controls'!I196 -> 88
B12: OK | C12: ='Checklist Annex Controls'!I197 -> 1
B13: OFI | C13: ='Checklist Annex Controls'!I198 -> 1
B14: nc- | C14: ='Checklist Annex Controls'!I199 -> 1
B15: NC+ | C15: ='Checklist Annex Controls'!I200 -> 2

Sheet Checklist Mgmt Clauses
A1: Structure | B1: Internal Audit checklist ISO/IEC 27001:2022 | C1: Included/Excluded | D1: Reference documents (add links where possible) Policy/Procedure/Manual | E1: Operational platform used to manage the control | F1: Owner/Responsible Person | G1: Operational Evidence witnessed / Proof found during audit | H1: Audit qualification (OK, OFI, nc-, NC+) | I1: Auditor Comments (extra info / interpretation) | J1: Relevant Process (add columns for other departments) | U1: Outsourced
B2: ISO/IEC 27001 Clauses | C2: By default all the management clause must be implemented.(no exclusions allowed) | D2: Fill in: add reference documents with links below like: policies, procedure, process documentation,.. Hint: add version nr | E2: Fill in (where to find evidence) | F2: Fill In (who to interview) | G2: Add aditional audit references (if different, add links to additional docs & reports) Other, incl interviewed people, metadata, system records, … Hint: add evidence, time and data of check | H2: Enter qualification with these codes OFI = opportunity for improvement NC+ = major nonconformity nc- = minor nc OK = all OK TBC = To be Checked | I2: Enter remarks | J2: Management | K2: HR | L2: CISO | M2: IT | N2: Development | O2: Legal | P2: Physical Security | Q2: Supplier Mgmt | R2: End user | S2: Other | T2: Community | U2: Yes/no
A3: 4 §0 | B3: 4 Context of the organization
A4: 4.1 §0 | B4: 4.1 Understanding the organization and its context
A5: 4.1 §1 | B5: The organization shall determine external and internal issues that are relevant to its purpose and that affect its ability to achieve the intended outcome(s) of its information security management system. | C5: Included | D5: For example, company mission, vision & value statement on website | E5: <where to find evidence> | F5: <who to talk to> | G5: <operational evidence> | H5: TBC | I5: <extra info> | J5: X | K5: X | U5: No
A6: 4.2 §0 | B6: 4.2 Understanding the needs and expectations of interested parties
A7: 4.2 §1 | B7: The organization shall determine: a) interested parties that are relevant to the information security management system; and b) the requirements of these interested parties relevant to information security. | C7: Included | D7: <policy/procedure/process definition> | E7: <where to find evidence> | F7: <who to talk to> | G7: <operational evidence> | H7: OK | I7: <extra info> | J7: X | K7: X | U7: No
A8: 4.3 §0 | B8: 4.3 Determining the scope of the information security management system
A9: 4.3 §1 | B9: The organization shall determine the boundaries and applicability of the information security management system to establish its scope. | C9: Included | H9: OFI | I9: <extra info> | J9: X | K9: X | U9: No
A10: 4.3 §2 | B10: When determining this scope, the organization shall consider: a) the external and internal issues referred to in 4.1; b) the requirements referred to in 4.2; and c) interfaces and dependencies between activities performed by the organization, and those that are performed by other organizations. | C10: Included | H10: nc- | I10: <extra info> | J10: X | K10: X | U10: No
A11: 4.3 §3 | B11: The scope shall be available as documented information. | C11: Included | H11: NC+ | I11: <extra info> | J11: X | K11: X | U11: No
A12: 4.4 §0 | B12: 4.4 Information security management system
A13: 4.4 §1 | B13: The organization shall establish, implement, maintain and continually improve an information security management system, in accordance with the requirements of this International Standard. | C13: Included | H13: OK | I13: <extra info> | J13: X | K13: X | U13: No
A14: 5 §0 | B14: 5 Leadership
A15: 5.1 §0 | B15: 5.1 Leadership and commitment
A16: 5.1 §1 | B16: Top management shall demonstrate leadership and commitment with respect to the information security management system by: a) ensuring the information security policy and the information security objectives are established and are compatible with the strategic direction of the organization; b) ensuring the integration of the information security management system requirements into the organization's processes; c) ensuring that the resources needed for the information security management system are available; d) communicating the importance of effective information security management and of conforming to the information security management system requirements; e) ensuring that the information security management system achieves its intended outcome(s); f) directing and supporting persons to contribute to the effectiveness of the information security management system; g) promoting continual improvement; and) supporting other relevant management roles to demonstrate their leadership as it applies to their areas of responsibility. | C16: Included | H16: OK | I16: <extra info> | J16: X | U16: No
A17: 5.2 §0 | B17: 5.2 Policy
A18: 5.2 §1 | B18: Top management shall establish an information security policy that: a) is appropriate to the purpose of the organization; b) includes information security objectives (see 6.2) or provides the framework for setting information security objectives; c) includes a commitment to satisfy applicable requirements related to information security; and d) includes a commitment to continual improvement of the information security management system. | C18: Included | H18: OK | I18: <extra info> | J18: X | K18: X | U18: No
A19: 5.2 §2 | B19: The information security policy shall: e) be available as documented information; f) be communicated within the organization; and g) be available to interested parties, as appropriate. | C19: Included | H19: OK | I19: <extra info> | J19: X | K19: X | U19: No
A20: 5.3 §0 | B20: 5.3 Organizational roles, responsibilities and authorities
A21: 5.3 §1 | B21: Top management shall ensure that the responsibilities and authorities for roles relevant to information security are assigned and communicated. | C21: Included | H21: OK | I21: <extra info> | J21: X | K21: X | L21: X | U21: No
A22: 5.3 §2 | B22: Top management shall assign the responsibility and authority for: a) ensuring that the information security management system conforms to the requirements of this International Standard; and b) reporting on the performance of the information security management system to top management. | C22: Included | H22: OK | I22: <extra info> | J22: X | K22: X | L22: X | U22: No
A23: 6 §0 | B23: 6 Planning
A24: 6.1 §0 | B24: 6.1 Actions to address risks and opportunities
A25: 6.1.1§2 | B25: 6.1.1 General
A26: 6.1.1§1 | B26: When planning for the information security management system, the organization shall consider the issues referred to in 4.1 and the requirements referred to in 4.2 and determine the risks and opportunities that need to be addressed to: a) ensure the information security management system can achieve its intended outcome(s); b) prevent, or reduce, undesired effects; and c) achieve continual improvement. | C26: Included | H26: OK | I26: <extra info> | J26: X | K26: X | L26: X | M26: X | N26: X | O26: X | P26: X | Q26: X | R26: X | S26: X | T26: X | U26: No
A27: 6.1.1§2 | B27: The organization shall plan: d) actions to address these risks and opportunities; and e) how to integrate and implement these actions into its information security management system processes; and evaluate the effectiveness of these actions. | C27: Included | H27: OK | I27: <extra info> | J27: X | K27: X | L27: X | M27: X | N27: X | O27: X | P27: X | Q27: X | R27: X | S27: X | T27: X | U27: No
A28: 6.1.2§0 | B28: 6.1.2 Information security risk assessment
A29: 6.1.2§1 | B29: The organization shall define and apply an information security risk assessment process that: a) establishes and maintains information security risk criteria that include:1) the risk acceptance criteria; and 2) criteria for performing information security risk assessments; b) ensures that repeated information security risk assessments produce consistent, valid and comparable results; c) identifies the information security risks:1) apply the information security risk assessment process to identify risks associated with the loss of confidentiality, integrity and availability for information within the scope of the information security management system; and2) identify the risk owners; d) analyses the information security risks:1) assess the potential consequences that would result if the risks identified in 6.1.2 c) 1) were to materialize;2) assess the realistic likelihood of the occurrence of the risks identified in 6.1.2 c) 1); and3) determine the levels of risk; e) evaluates the information security risks:1) compare the results of risk analysis with the risk criteria established in 6.1.2 a); and2) prioritize the analysed risks for risk treatment. | C29: Included | D29: Risk register, DPIA, … | H29: OK | I29: <extra info> | J29: X | L29: X | U29: No
A30: 6.1.2§2 | B30: The organization shall retain documented information about the information security risk assessment process. | C30: Included | H30: OK | I30: <extra info> | J30: X | L30: X
A31: 6.1.3§0 | B31: 6.1.3 Information security risk treatment
A32: 6.1.3§1 | B32: The organization shall define and apply an information security risk treatment process to: a) select appropriate information security risk treatment options, taking account of the risk assessment results; b) determine all controls that are necessary to implement the information security risk treatment option(s) chosen; c) compare the controls determined in 6.1.3 b) above with those in Annex A and verify that no necessary controls have been omitted; d) produce a Statement of Applicability that contains the necessary controls (see 6.1.3 b) and c)) and justification for inclusions, whether they are implemented or not, and the justification for exclusions of controls from Annex A; e) formulate an information security risk treatment plan; and f) obtain risk owners’ approval of the information security risk treatment plan and acceptance of the residual information security risks. The organization shall retain documented information about the information security risk treatment process. | C32: Included | D32: Risk regsiter | H32: NC+ | I32: <extra info> | J32: X | L32: X | U32: No
A33: 6.1.3§2 | B33: Statement of apllicability: The organization shall retain documented information about the information security risk treatment process. The risk assessment covers the scope of the management system. The client granted the access to all necessary organizational documented information. | C33: Included | H33: OK | I33: <extra info> | J33: X | L33: X | U33: No
A34: 6.2§0 | B34: 6.2 Information security objectives and planning to achieve them
A35: 6.2§1 | B35: The organization shall establish information security objectives at relevant functions and levels. | C35: Included | H35: OK | I35: <extra info> | J35: X | L35: X | U35: No
A36: 6.2§2 | B36: The information security objectives shall: a) be consistent with the information security policy; b) be measurable (if practicable); c) take into account applicable information security requirements, and risk assessment and risk treatment results; d) be communicated; and e) be updated as appropriate. | C36: Included | H36: OK | I36: <extra info> | J36: X | L36: X | U36: No
A37: 6.2§2 | B37: The organization shall retain documented information on the information security objectives. | C37: Included | H37: OK | I37: <extra info> | J37: X | L37: X | U37: No
A38: 6.2§3 | B38: When planning how to achieve its information security objectives, the organization shall determine: f) what will be done; g) what resources will be required; h) who will be responsible; i) when it will be completed; and j) how the results will be evaluated. | C38: Included | H38: OK | I38: <extra info> | J38: X | L38: X | U38: No
A39: 6.3§0 | B39: 6.3 Planning of changes
A40: 6.3§1 | B40: When the organization determines the need for changes to the information security management system, the changes shall be carried out in a planned manner. | C40: Included | H40: OK | I40: <extra info> | J40: X | L40: X | U40: No
...

Sheet Checklist Annex Controls
B1: Internal Audit checklist ISO/IEC 27001:2022 | C1: Operational capability | D1: Included/Excluded | E1: Reference documents (add links where possible) | F1: Operational platform used to manage the control | G1: Owner/Responsible team | H1: audit evidence / sample record references witnessed / operational proof | I1: Audit qualification (white = TC, green=OK, yellow=OFI, orange=minor NC, red = major NC) | J1: Auditor Comments (extra info / interpretation) | K1: Relevant Process Owner (you can insert or remove columns to add/remove departments) | V1: Outsourced
B2: ISO/IEC 27001 Controls | C2: Group (#Tag) | E2: TO DO (add documents with links below) like: policies, procedure, process documentation,.. Hint: add version nr | F2: Fill in (where to find evidence) | G2: Fill In (who to interview) | H2: Add aditional audit references (if different, add links to additional docs & reports) Other, incl interviewed people, metadata, system records, … Hint: add evidence, time and data of check | I2: Enter qualification with these codes OFI = opportunity for improvement NC+ = major nonconformity nc- = minor nc OK = all OK TBC = To be Checked | J2: Enter remarks | K2: Management | L2: HR | M2: CISO | N2: IT | O2: Development | P2: Legal | Q2: Physical Security | R2: Supplier Mgmt | S2: End user | T2: Other | U2: Community | V2: Yes/ No
A3: A.5$0 | B3: A.5 Organisational controls
A4: A.5.1$1 | B4: A.5.1 Policies for information security
A5: A.5.1$2 | B5: Information security policy and topic-specific policies shall be defined, approved by management, published, communicated to and acknowledged by relevant personnel and relevant interested parties, and reviewed at planned intervals and if significant changes occur. | C5: #Governance | D5: Included | I5: TBC | J5: <extra info> | K5: x | V5: No
A6: A.5.2$1 | B6: A.5.2 Information security roles and responsibilities
A7: A.5.2$2 | B7: Information security roles and responsibilities shall be defined and allocated according to the organization needs. | C7: #Governance | D7: Included | I7: OK | J7: <extra info> | K7: x | L7: x | M7: x | V7: No
A8: A.5.3$1 | B8: A.5.3 Segregation of duties
A9: A.5.3$2 | B9: Conflicting duties and conflicting areas of responsibility shall be segregated. | C9: #Governance #Identity_and_access_management | D9: Included | I9: OFI | J9: <extra info> | K9: x | L9: x | M9: x | V9: No
A10: A.5.4$1 | B10: A.5.4 Management responsibilities
A11: A.5.4$2 | B11: Management shall require all personnel to apply information security in accordance with the established information security policy, topic-specific policies and procedures of the organization. | C11: #Governance | D11: Included | I11: nc- | J11: <extra info> | K11: x | V11: No
A12: A.5.5$1 | B12: A.5.5 Contact with authorities
A13: A.5.5$2 | B13: The organization shall establish and maintain contact with relevant authorities. | C13: #Governance | D13: Included | I13: NC+ | J13: <extra info> | K13: x | M13: x | P13: x | V13: No
A14: A.5.6$1 | B14: A.5.6 Contact with special interest groups
A15: A.5.6$2 | B15: The organization shall establish and maintain contact with special interest groups or other specialist security forums and professional associations. | C15: #Governance | D15: Included | I15: TBC | J15: <extra info> | K15: x | L15: x | M15: x | N15: x | O15: x | P15: x | Q15: x | R15: x | V15: No
A16: A.5.7$1 | B16: A.5.7 Threat intelligence
A17: A.5.7$2 | B17: Information relating to information security threats shall be collected and analysed to produce threat intelligence. | C17: #Threat_and_vulnerability_management | D17: Included | I17: TBC | J17: <extra info> | K17: x | M17: x | N17: x | O17: x | V17: No
A18: A.5.8$1 | B18: A.5.8 Information security in project management
A19: A.5.8$2 | B19: Information security shall be integrated into project management. | C19: #Governance | D19: Included | I19: TBC | J19: <extra info> | N19: x | O19: x | V19: No
A20: A.5.9$1 | B20: A.5.9 Inventory of information and other associated assets
A21: A.5.9$2 | B21: An inventory of information and other associated assets, including owners, shall be developed and maintained. | C21: #Asset_management | D21: Included | I21: TBC | J21: <extra info> | M21: x | N21: x | O21: x | V21: No
A22: A.5.10$1 | B22: A.5.10 Acceptable use of information and other associated assets
A23: A.5.10$2 | B23: Rules for the acceptable use and procedures for handling information and other associated assets shall be identified, documented and implemented. | C23: #Asset_management #Information_protection | D23: Included | I23: TBC | J23: <extra info> | M23: x | N23: x | V23: No
A24: A.5.11$1 | B24: A.5.11 Return of assets
A25: A.5.11$2 | B25: Personnel and other interested parties as appropriate shall return all the organization’s assets in their possession upon change or termination of their employment, contract or agreement. | C25: #Asset_management | D25: Included | I25: TBC | J25: <extra info> | N25: x | S25: x | V25: No
A26: A.5.12$1 | B26: A.5.12 Classification of information
A27: A.5.12$2 | B27: Information shall be classified according to the information security needs of the organization based on confidentiality, integrity, availability and relevant interested party requirements. | C27: #Information_protection | D27: Included | I27: TBC | J27: <extra info> | M27: x | N27: x | V27: No
A28: A.5.13$1 | B28: A.5.13 Labelling of information
A29: A.5.13$2 | B29: An appropriate set of procedures for information labelling shall be developed and implemented in accordance with the information classification scheme adopted by the organization. | C29: #Information_protection | D29: Included | I29: TBC | J29: <extra info> | M29: x | N29: x | V29: No
A30: A.5.14$1 | B30: A.5.14 Information transfer
A31: A.5.14$2 | B31: Information transfer rules, procedures, or agreements shall be in place for all types of transfer facilities within the organization and between the organization and other parties. | C31: #Asset_management #Information_protection | D31: Included | I31: TBC | J31: <extra info> | K31: x | M31: x | N31: x | P31: x | S31: x | V31: No
A32: A.5.15$1 | B32: A.5.15 Access control
A33: A.5.15$2 | B33: Rules to physical and logical access to information and other associated assets shall be established and implemented based on business and information security requirements. | C33: #Identity_and_access_management | D33: Included | I33: TBC | J33: <extra info> | M33: x | N33: x | V33: No
A34: A.5.16$1 | B34: A.5.16 Identity management
A35: A.5.16$2 | B35: The full life cycle of identities shall be managed. | C35: #Identity_and_access_management | D35: Included | I35: TBC | J35: <extra info> | L35: x | M35: x | N35: x | V35: No
A36: A.5.17$1 | B36: A.5.17 Authentication information
A37: A.5.17$2 | B37: Allocation and management of authentication information shall be led by a management process, including advising personnel on appropriate handling of authentication information. | C37: #Identity_and_access_management | D37: Included | I37: TBC | J37: <extra info> | N37: x | V37: No
A38: A.5.18$1 | B38: A.5.18 Access rights
A39: A.5.18$2 | B39: Access rights to information and other associated assets shall be provisioned, reviewed, modified and removed in accordance with the organization’s topic-specific policy on and rules for access . | C39: #Identity_and_access_management | D39: Included | I39: TBC | J39: <extra info> | M39: x | N39: x | V39: No
A40: A.5.19$1 | B40: A.5.19 Information security in supplier relationships
...

Sheet Lookup Tables
A1: Audit types | B1: Boolean
A2: Certification audit (Year 0) | B2: Yes
A3: Surveillance Audit (Year 1) | B3: No
A4: Surveillance Audit (Year 2)
A5: Recertification Audit (Year 3)
A6: Pre-audit (preparation for certification)
