Workbook

Sheet Teams
A1: All audit participants | B1: Responsible | C1: Members to interview | D1: Controls group
A2: Auditor | D2: All
A3: ='Control to team mapping'!D2 -> Management Team | D3: 4.1; 4.2; 4.3; 4.4; 5.1; 5.2; 5.3; 6.1; 6.2; 9.2; 9.3; 10.1; 10.2; A.5.1; A.6.1; A.6.2; 6.3
A4: ='Control to team mapping'!E2 -> Security officer / ISMS Project
A5: ='Control to team mapping'!F2 -> Physical Security | D5: 7.5, A11
A6: ='Control to team mapping'!G2 -> IT Operations & Support | D6: 6.1 ;7.4 ;7.5 ;8.2 ;8.3 ;9.1 ;10.1 ;10.2 ;A.5.1;
A7: ='Control to team mapping'!H2 -> Legal & Regulatory | D7: 6.1 ;7.3 ;7.4 ;7.5 ;8.2 ;8.3 ;9.1 ;A.5.1 ;A.6.2 ;A.8.1 ;A.8.2 ;A.8.3 ;A.9.1 ;A.9.3 ;A.9.4 ;A.11.1 ;A.11.2 ;A.12.1 ;A.12.2 ;A.12.3 ;A.12.4 ;A.12.5 ;A.12.6 ;A.12.7 ;A.13.1 ;A.13.2 ;A.14.1 ;A.14.2 ;A.14.3 ;A.15.1 ;A.15.2 ;A.16.1 ;A.17.1 ;A.17.2 ;A.18.2;
A8: ='Control to team mapping'!K2 -> HR & Office management | D8: 6.1 ;7.1 ;7.5 ;8.1 ;A.18.1;
A9: ='Control to team mapping'!L2 -> Supplier Management | D9: 7.1 ;7.2 ;7.3 ;7.5 ;9.1 ;A.6.1 ;A.6.2 ;A.7.1 ;A.7.2 ;A.7.3 ;A.9.3;
A10: ='Control to team mapping'!M2 -> Communication & Marketing | D10: 7.5 ;9.1 ;A.13.2
A11: ='Control to team mapping'!N2 -> Commercial & Sales | D11: 7.4; 7.5
A12: ='Control to team mapping'!O2 -> Customer Support (Incident/Ticketing) | D12: 7.4; 7.5 ;A.13.2
A13: ='Control to team mapping'!P2 -> Product Management & Service Offering | D13: A.13.2 ;A.14.1 ;A.14.2 ;A.14.3;
A14: ='Control to team mapping'!Q2 -> Quality Management | D14: 7.4 ;7.5 ;
A15: ='Control to team mapping'!D17 -> X | D15: 7.4 ;7.5 ;8.2 ;8.3 ;A.13.2 ;A.15.2 ;A.18.1;
A16: ='Control to team mapping'!E17 -> X | D16: 7.5 ;A.13.2
A17: ='Control to team mapping'!D19 -> 0 | D17: 7.5 ;A.13.2

Sheet Control to team mapping
C1: Level | D1: 1 | E1: 1 | F1: 1 | G1: 1 | H1: 1 | I1: 1 | J1: 1 | K1: 1 | L1: 1 | M1: 1 | N1: 3 | O1: 2 | P1: 3 | Q1: 3 | R1: 3
A2: ISO27001 Clauses & Annex | B2: Departments | D2: Management Team | E2: Security officer / ISMS Project | F2: Physical Security | G2: IT Operations & Support | H2: Legal & Regulatory | I2: GDPR & Privacy | J2: Cybersecurity & Cloud$ | K2: HR & Office management | L2: Supplier Management | M2: Communication & Marketing | N2: Commercial & Sales | O2: Customer Support (Incident/Ticketing) | P2: Product Management & Service Offering | Q2: Quality Management | R2: Customer Service Delivery | S2: <other to add> | T2: <other to add> | U2: Internal audit Coverage
A3: Internal audit Coverage | B3: Initial Audit (Y0) | D3: X | E3: X | F3: X | G3: X | H3: X | I3: X | J3: X | K3: X | L3: X | M3: X | N3: X | O3: X | P3: X | Q3: X | R3: X | S3: X | T3: x | U3: =COUNTA(D3:T3) -> 17 | V3: 1
B4: Surveillance 1 (Y0+1) | D4: X | E4: X | F4: X | G4: X | N4: X | P4: X | Q4: X | U4: =COUNTA(E4:T4) -> 6 | V4: 0.33
B5: Surveillance 2 (Y0+2) | D5: X | E5: X | F5: X | H5: X | K5: X | M5: X | O5: X | R5: X | U5: =COUNTA(E5:T5) -> 7 | V5: 0.33
B6: Recert (Y0+3)) | D6: X | E6: X | F6: X | G6: X | H6: X | I6: X | J6: X | K6: X | L6: X | M6: X | N6: X | O6: X | P6: X | Q6: X | R6: X | S6: X | T6: X | U6: =COUNTA(D6:T6) -> 17 | V6: 0.66
A7: Main Clauses | B7: 4 | C7: Context of organisation | V7: =COUNTIF(U8:U11,"FALSE")=0 -> TRUE
B8: 4.1 | C8: Understanding context | D8: X | E8: X | U8: =COUNTA(D8:T8)>0 -> TRUE
B9: 4.2 | C9: Interested parties | D9: X | E9: X | U9: =COUNTA(D9:T9)>0 -> TRUE
B10: 4.3 | C10: Scope | D10: X | E10: X | U10: =COUNTA(D10:T10)>0 -> TRUE
B11: 4.4 | C11: ISMS | D11: X | E11: X | U11: =COUNTA(D11:T11)>0 -> TRUE
B12: 5 | C12: Leadership
B13: 5.1 | C13: Leadership and commitment | D13: X | U13: =COUNTA(D13:T13)>0 -> TRUE
B14: 5.2 | C14: Policy | D14: X | U14: =COUNTA(D14:T14)>0 -> TRUE
B15: 5.3 | C15: Organization | D15: X | U15: =COUNTA(D15:T15)>0 -> TRUE
B16: 6 | C16: Planning
B17: 6.1 | C17: Risk management Planning | D17: X | E17: X | G17: X | H17: X | U17: =COUNTA(D17:T17)>0 -> TRUE
B18: 6.1.1 | C18: Risk management - Continual Improvement
B19: 6.1.2 | C19: Risk assessment
B20: 6.1.3 | C20: Risk treatment & SoA
B21: 6.2 | C21: Infosec objectives | D21: X | U21: =COUNTA(D21:T21)>0 -> TRUE
B22: 7 | C22: Support
B23: 7.1 | C23: Resources | D23: X | H23: X | K23: X | U23: =COUNTA(D23:T23)>0 -> TRUE
B24: 7.2 | C24: Competence | D24: X | K24: X | U24: =COUNTA(D24:T24)>0 -> TRUE
B25: 7.3 | C25: Awareness | D25: X | G25: X | K25: X | U25: =COUNTA(D25:T25)>0 -> TRUE
B26: 7.4 | C26: Communication | D26: X | E26: X | G26: X | M26: X | O26: X | P26: X | Q26: X | U26: =COUNTA(D26:T26)>0 -> TRUE
B27: 7.5 | C27: Documentation | D27: X | E27: X | F27: X | G27: X | H27: X | K27: X | M27: X | N27: X | O27: X | P27: X | Q27: X | R27: X | U27: =COUNTA(D27:T27)>0 -> TRUE
B28: 7.5.1 | C28: Documented information available | Q28: X | U28: =COUNTA(D28:T28)>0 -> TRUE
B29: 7.5.2 | C29: Creating & updating documentation | R29: X | U29: =COUNTA(D29:T29)>0 -> TRUE
B30: 7.5.3 | C30: Document control | U30: =COUNTA(D30:T30)>0 -> FALSE
B31: 8 | C31: Operation
B32: 8.1 | C32: Operational planning and control | H32: X | U32: =COUNTA(D32:T32)>0 -> TRUE
B33: 8.2 | C33: Risk assessment | D33: X | E33: X | G33: X | Q33: X | U33: =COUNTA(D33:T33)>0 -> TRUE
B34: 8.3 | C34: Risk treatment | D34: X | E34: X | G34: X | Q34: X | U34: =COUNTA(D34:T34)>0 -> TRUE
B35: 9 | C35: Performance evaluation
B36: 9.1 | C36: Performance Monitoring | D36: X | E36: X | G36: X | K36: X | N36: X | U36: =COUNTA(D36:T36)>0 -> TRUE
B37: 9.2 | C37: Internal Audit | D37: X | U37: =COUNTA(D37:T37)>0 -> TRUE
B38: 9.2.1 | C38: General
B39: 9.2.2 | C39: Internal audit program
B40: 9.3 | C40: Management Review | D40: X | U40: =COUNTA(D40:T40)>0 -> TRUE
...

Sheet Advanced Team control mapping
E1: ISO27001 Clauses & Annex | J1: ISO27001 Main Clauses | AF1: ISO27001 Annex
E2: Internal audit Coverage (example) | J2: 4.1 | K2: 4.2 | L2: 4.3 | M2: 4.4 | N2: 5.1 | O2: 5.2 | P2: 5.3 | Q2: 6.1 | R2: 6.2 | S2: 7.1 | T2: 7.2 | U2: 7.3 | V2: 7.4 | W2: 7.5 | X2: 8.1 | Y2: 8.2 | Z2: 8.3 | AA2: 9.1 | AB2: 9.2 | AC2: 9.3 | AD2: 10.1 | AE2: 10.2 | AF2: A.5.1 | AG2: A.6.1 | AH2: A.6.2 | AI2: A.7.1 | AJ2: A.7.2 | AK2: A.7.3 | AL2: A.8.1 | AM2: A.8.2 | AN2: A.8.3 | AO2: A.9.1 | AP2: A.9.2 | AQ2: A.9.3 | AR2: A.9.4 | AS2: A.10.1 | AT2: A.11.1 | AU2: A.11.2 | AV2: A.12.1 | AW2: A.12.2 | AX2: A.12.3 | AY2: A.12.4 | AZ2: A.12.5 | BA2: A.12.6 | BB2: A.12.7 | BC2: A.13.1 | BD2: A.13.2 | BE2: A.14.1 | BF2: A.14.2 | BG2: A.14.3 | BH2: A.15.1 | BI2: A.15.2 | BJ2: A.16.1 | BK2: A.17.1 | BL2: A.17.2 | BM2: A.18.1 | BN2: A.18.2
A3: Focus Areas Task/Role description | B3: Sample Department (You can assign multiple tasks to same team) | C3: Typical / Possible coverage of ISO27001 Clause/Annex | D3: Importance | E3: Initial Audit (Y0) | F3: Surveillance 1 (Y0+1) | G3: Surveillance 2 (Y0+2) | H3: Recert (Y0+3)) | I3: Clauses/Annex controls covered | J3: Context of organisation | K3: Interested parties | L3: Scope | M3: ISMS | N3: Leadership and commitment | O3: Policy | P3: Organizational Roles, Resposibilities and authorities | Q3: Risk management | R3: Infosec objectives | S3: Resources | T3: Competence | U3: Awareness | V3: Communication | W3: Documentation | X3: Operational planning | Y3: Risk assessment | Z3: Risk treatment | AA3: Performance Monitoring | AB3: Internal Audit | AC3: Management Review | AD3: Non-conformity | AE3: Continual Improvement | AF3: Infosec Policies | AG3: Internal organisation | AH3: Mobile devices and telework | AI3: HR Prior to employment | AJ3: HR during employment | AK3: HR Termination or change | AL3: Asset Ownership | AM3: Information Classification | AN3: Media handling | AO3: Access control / Business | AP3: User access Management | AQ3: User Responsibilities | AR3: System and Appl access control | AS3: Cryptography | AT3: Secure Areas | AU3: Equipment | AV3: Operaional procedures | AW3: Malware protection | AX3: Backup | AY3: Logging and monitoring | AZ3: Control of operational software | BA3: Tech Vulnerability Management | BB3: Info systems Audit | BC3: Network security | BD3: Information transfer | BE3: Sec Requirements of IS | BF3: Sec in dev & support processe | BG3: Test data | BH3: Information security in supplier relations | BI3: Supplier delivery Management | BJ3: Incident management | BK3: Information Security Continuity | BL3: Redundancy | BM3: Compliance with Legal and contractual requirement | BN3: Information Security review
A4: Internal audit Coverage | E4: =COUNTA(E9:E38) -> 30 | F4: =COUNTA(F9:F38) -> 30 | G4: =COUNTA(G9:G38) -> 3 | H4: =COUNTA(H9:H38) -> 30 | I4: =AND(J4:BN4) -> TRUE | J4: =COUNTA(J7:J38)>0 -> TRUE | K4: =COUNTA(K7:K38)>0 -> TRUE | L4: =COUNTA(L7:L38)>0 -> TRUE | M4: =COUNTA(M7:M38)>0 -> TRUE | N4: =COUNTA(N7:N38)>0 -> TRUE | O4: =COUNTA(O7:O38)>0 -> TRUE | P4: =COUNTA(P7:P38)>0 -> TRUE | Q4: =COUNTA(Q7:Q38)>0 -> TRUE | ... Y4: =COUNTA(Y7:Y38)>0 -> TRUE | Z4: =COUNTA(þ4:þ26)>0 -> TRUE | AA4: =COUNTA(AA7:AA38)>0 -> TRUE | AB4: =COUNTA(AB7:AB38)>0 -> TRUE | AC4: =COUNTA(AC7:AC38)>0 -> TRUE | AD4: =COUNTA(AD7:AD38)>0 -> TRUE | AE4: =COUNTA(AE7:AE38)>0 -> TRUE | AF4: =COUNTA(AF7:AF38)>0 -> TRUE | AG4: =COUNTA(AG7:AG38)>0 -> TRUE | AH4: =COUNTA(AH7:AH38)>0 -> TRUE | ... AY4: =COUNTA(AY7:AY38)>0 -> TRUE | AZ4: =COUNTA(Aþ4:Aþ26)>0 -> TRUE | BA4: =COUNTA(BA7:BA38)>0 -> TRUE | BB4: =COUNTA(BB7:BB38)>0 -> TRUE | BC4: =COUNTA(BC7:BC38)>0 -> TRUE | BD4: =COUNTA(BD7:BD38)>0 -> TRUE | BE4: =COUNTA(BE7:BE38)>0 -> TRUE | BF4: =COUNTA(BF7:BF38)>0 -> TRUE | BG4: =COUNTA(BG7:BG38)>0 -> TRUE | BH4: =COUNTA(BH7:BH38)>0 -> TRUE | ... BN4: =COUNTA(BN7:BN38)>0 -> TRUE
E5: 1 | F5: 0.33 | G5: 0.33 | H5: 0.66
J6: =COUNTA(J7:J38) -> 1 | K6: =COUNTA(K7:K38) -> 1 | L6: =COUNTA(L7:L38) -> 2 | M6: =COUNTA(M7:M38) -> 2 | N6: =COUNTA(N7:N38) -> 1 | O6: =COUNTA(O7:O38) -> 2 | P6: =COUNTA(P7:P38) -> 3 | Q6: =COUNTA(Q7:Q38) -> 3 | ... BN6: =COUNTA(BN7:BN38) -> 9
A7: Management | B7: Management team | C7: Accountability Clause 9.3 | D7: Strategic/High | E7: MUST | F7: PRIO | G7: PRIO | H7: MUST | I7: =COUNTA(J7:BN7) -> 26 | J7: þ | K7: þ | L7: þ | N7: þ | O7: þ | P7: þ | R7: þ | S7: þ | T7: þ | U7: þ | V7: þ | W7: þ | X7: þ | AA7: þ | AB7: þ | AC7: þ | AD7: þ | AE7: þ | AF7: þ | AG7: þ | AH7: þ | AL7: þ | AV7: þ | BD7: þ | BM7: þ | BN7: þ
A8: CISO | B8: Responsible for ISMS | C8: Security Operations | D8: Strategic/High | E8: MUST | F8: PRIO | G8: PRIO | H8: MUST | I8: =COUNTA(J8:BN8) -> 22 | L8: þ | M8: þ | O8: þ | P8: þ | Q8: þ | R8: þ | U8: þ | V8: þ | W8: þ | X8: þ | Y8: þ | Z8: þ | AA8: þ | AB8: þ | AC8: þ | AD8: þ | AE8: þ | AF8: þ | AM8: þ | AV8: þ | BH8: þ | BN8: þ
A9: ISMS Project / Support | B9: ISMS team | C9: Clause 4.4 | D9: Strategic/High | E9: MUST | F9: PRIO | G9: PRIO | H9: MUST | I9: =COUNTA(J9:BN9) -> 15 | M9: þ | Q9: þ | U9: þ | V9: þ | W9: þ | X9: þ | Y9: þ | Z9: þ | AA9: þ | AB9: þ | AD9: þ | AE9: þ | AF9: þ | AM9: þ | AV9: þ
A10: Risk management | B10: Risk Governance Team | C10: Clause 6 Clause 8 | D10: Strategic/High | E10: MUST | F10: PRIO | G10: PRIO | H10: MUST | I10: =COUNTA(J10:BN10) -> 12 | Q10: þ | V10: þ | W10: þ | X10: þ | Y10: þ | Z10: þ | AA10: þ | AD10: þ | AE10: þ | AF10: þ | AV10: þ | AY10: þ
A11: Internal audit | B11: Internal Audit Team | C11: Clause 9.1 & 9.2 | D11: Strategic/High | E11: MUST | F11: MUST | G11: MUST | H11: MUST | I11: =COUNTA(J11:BN11) -> 6 | W11: þ | X11: þ | AA11: þ | AB11: þ | AF11: þ | AV11: þ
A12: HR | B12: HR Team | C12: Clause 7 | D12: Tactical/Medium | E12: MUST | F12: S1 or S2 | H12: MUST | I12: =COUNTA(J12:BN12) -> 18 | P12: þ | S12: þ | T12: þ | U12: þ | V12: þ | W12: þ | X12: þ | AA12: þ | AF12: þ | AG12: þ | AH12: þ | AI12: þ | AJ12: þ | AK12: þ | AQ12: þ | AV12: þ | BK12: þ | BM12: þ
A13: Legal & Regulatory | B13: Legal team | C13: A.18 | D13: Tactical/Medium | E13: MUST | F13: S1 or S2 | H13: MUST | I13: =COUNTA(J13:BN13) -> 6 | W13: þ | X13: þ | AA13: þ | AF13: þ | AV13: þ | BM13: þ
A14: BCM & DRP | B14: Single team/Per department | C14: Essential | D14: Tactical/Medium | E14: MUST | F14: S1 or S2 | H14: MUST | I14: =COUNTA(J14:BN14) -> 9 | U14: þ | W14: þ | X14: þ | AA14: þ | AF14: þ | AV14: þ | BG14: þ | BK14: þ | BL14: þ
A15: Supplier Management | B15: Single team/Per department | C15: A.15 | D15: Tactical/Medium | E15: MUST | F15: S1 or S2 | H15: MUST | I15: =COUNTA(J15:BN15) -> 7 | U15: þ | W15: þ | X15: þ | AA15: þ | AF15: þ | AV15: þ | BM15: þ
A16: Physical Security | B16: Building management/logistics | C16: A.11 | D16: Operational/Low | E16: MUST | F16: S1 or S2 | H16: MUST | I16: =COUNTA(J16:BN16) -> 14 | U16: þ | W16: þ | X16: þ | AA16: þ | AF16: þ | AP16: þ | AT16: þ | AU16: þ | AV16: þ | AY16: þ | BB16: þ | BH16: þ | BL16: þ | BN16: þ
A17: Asset Management | B17: Typically part of IT operations | C17: A.8 | D17: Operational/Low | E17: MUST | F17: S1 or S2 | H17: MUST | I17: =COUNTA(J17:BN17) -> 6 | W17: þ | X17: þ | AA17: þ | AF17: þ | AV17: þ | AY17: þ
A18: Access Control | B18: Typically part of IT operations | C18: A.9 | D18: Operational/Low | E18: MUST | F18: S1 or S2 | H18: MUST | I18: =COUNTA(J18:BN18) -> 7 | W18: þ | X18: þ | AA18: þ | AF18: þ | AV18: þ | AY18: þ | BN18: þ
A19: IT Operations & Support | B19: IT Operations & Support | C19: A.12 | D19: Operational/Low | E19: MUST | F19: S1 or S2 | H19: MUST | I19: =COUNTA(J19:BN19) -> 37 | U19: þ | V19: þ | W19: þ | X19: þ | Y19: þ | Z19: þ | AA19: þ | AB19: A.12.7.1 | AF19: þ | AH19: þ | AL19: þ | AM19: þ | AN19: þ | AO19: þ | AQ19: þ | AR19: þ | AS19: þ | AT19: þ | AU19: þ | AV19: þ | AW19: þ | AX19: þ | AY19: þ | AZ19: þ | BA19: þ | BB19: þ | BC19: þ | BD19: þ | BE19: þ | BF19: þ | BG19: þ | BH19: þ | BI19: þ | BJ19: þ | BK19: þ | BL19: þ | BN19: þ
A20: Internal IT Incident mgmt | B20: IT Help desk / Ticketing | C20: A.16 | D20: Operational/Low | E20: MUST | F20: S1 or S2 | H20: MUST | I20: =COUNTA(J20:BN20) -> 7 | W20: þ | X20: þ | AA20: þ | AE20: þ | AF20: þ | AV20: þ | BJ20: þ
A21: Software Development | B21: Depends company activity | C21: A.14 | D21: Operational/Low | E21: MUST | F21: S1 or S2 | H21: MUST | I21: =COUNTA(J21:BN21) -> 10 | T21: þ | U21: þ | W21: þ | X21: þ | AA21: þ | AF21: þ | AV21: þ | BF21: þ | BG21: þ | BN21: þ
A22: Software Acquisition & Purchase | B22: Depends company activity | C22: A.14 | D22: Operational/Low | E22: MUST | F22: S1 or S2 | H22: MUST | I22: =COUNTA(J22:BN22) -> 9 | U22: þ | W22: þ | X22: þ | AA22: þ | AF22: þ | AV22: þ | BF22: þ | BG22: þ | BN22: þ
A23: IT/Dev Project Mgmt | B23: IT | C23: A.12 | D23: Operational/Low | E23: MUST | F23: S1 or S2 | H23: MUST | I23: =COUNTA(J23:BN23) -> 7 | W23: þ | X23: þ | AA23: þ | AE23: þ | AF23: þ | AV23: þ | BF23: þ
A24: Network security | B24: Typically part of IT operations | C24: A.13 | D24: Operational/Low | E24: MUST | F24: S1 or S2 | H24: MUST | I24: =COUNTA(J24:BN24) -> 10 | W24: þ | X24: þ | AA24: þ | AF24: þ | AV24: þ | AY24: þ | BJ24: þ | BK24: þ | BL24: þ | BN24: þ
A25: Cryptography | B25: IT Operations & Support | C25: A.10 | D25: Operational/Low | E25: MUST | F25: S1 or S2 | H25: MUST | I25: =COUNTA(J25:BN25) -> 8 | W25: þ | X25: þ | AF25: þ | AS25: þ | AV25: þ | BC25: þ | BD25: þ | BM25: þ
A26: Penetration testing/Tech Review | B26: IT | C26: A.18.2 | D26: Operational/Low | E26: MUST | F26: S1 or S2 | H26: MUST | I26: =COUNTA(J26:BN26) -> 6 | W26: þ | X26: þ | AE26: þ | AF26: þ | AV26: þ | BN26: þ
A27: DPO (Data protection) | B27: DPO or Legal team | C27: A.18.1 | D27: Operational/Low | E27: MUST | F27: S1 or S2 | H27: MUST | I27: =COUNTA(J27:BN27) -> 9 | T27: þ | U27: þ | V27: þ | W27: þ | X27: þ | AA27: þ | AF27: þ | AV27: þ | BM27: þ
A28: Finance | B28: Internal Team | C28: Resources | D28: Operational/Low | E28: MUST | F28: S1 or S2 | H28: MUST | I28: =COUNTA(J28:BN28) -> 7 | S28: þ | W28: þ | X28: þ | AA28: þ | AF28: þ | AV28: þ | BM28: þ
A29: Product Development | B29: Business/External Facing | C29: A.14/A.12 | D29: Operational/Low | E29: MUST | F29: S1 or S2 | H29: MUST | I29: =COUNTA(J29:BN29) -> 9 | W29: þ | X29: þ | AA29: þ | AF29: þ | AV29: þ | BD29: þ | BE29: þ | BF29: þ | BG29: þ
A30: Sales | B30: Business/External Facing | C30: Business Support | D30: Operational/Low | E30: MUST | F30: S1 or S2 | H30: MUST | I30: =COUNTA(J30:BN30) -> 6 | W30: þ | X30: þ | AA30: þ | AF30: þ | AV30: þ | BD30: þ
A31: Marketing | B31: Business/External Facing | C31: Business Support | D31: Operational/Low | E31: MUST | F31: S1 or S2 | H31: MUST | I31: =COUNTA(J31:BN31) -> 8 | U31: þ | V31: þ | W31: þ | X31: þ | AA31: þ | AF31: þ | AV31: þ | BD31: þ
A32: Delivery to customer | B32: Business/External Facing | C32: Business Support | D32: Operational/Low | E32: MUST | F32: S1 or S2 | H32: MUST | I32: =COUNTA(J32:BN32) -> 4 | W32: þ | X32: þ | AF32: þ | AV32: þ
A33: Customer Relations | B33: Business/External Facing | C33: Business Support | D33: Operational/Low | E33: MUST | F33: S1 or S2 | H33: MUST | I33: =COUNTA(J33:BN33) -> 5 | W33: þ | X33: þ | AA33: þ | AF33: þ | AV33: þ
A34: Customer help desk & incidents | B34: Business/External Facing | C34: A.16 | D34: Operational/Low | E34: MUST | F34: S1 or S2 | H34: MUST | I34: =COUNTA(J34:BN34) -> 8 | V34: þ | W34: þ | X34: þ | AA34: þ | AE34: þ | AF34: þ | AV34: þ | BJ34: þ
A35: Business Project Management | B35: Business/External Facing | C35: A.12 | D35: Operational/Low | E35: MUST | F35: S1 or S2 | H35: MUST | I35: =COUNTA(J35:BN35) -> 6 | W35: þ | X35: þ | AA35: þ | AE35: þ | AF35: þ | AV35: þ
A36: Purchase | B36: IT / Business | C36: A.14 | D36: Operational/Low | E36: MUST | F36: S1 or S2 | H36: MUST | I36: =COUNTA(J36:BN36) -> 5 | W36: þ | X36: þ | AA36: þ | AF36: þ | AV36: þ
A37: Quality Management | B37: Internal Team | C37: Management Support | D37: OPTIONAL | E37: MUST | F37: S1 or S2 | H37: MUST | I37: =COUNTA(J37:BN37) -> 11 | V37: þ | W37: þ | X37: þ | Y37: þ | Z37: þ | AA37: þ | AF37: þ | AV37: þ | BD37: þ | BI37: þ | BM37: þ
A38: <other to add> | E38: MUST | F38: S1 or S2 | H38: MUST | I38: =COUNTA(J38:BN38) -> 5 | W38: þ | X38: þ | AA38: þ | AF38: þ | AV38: þ

Sheet Interne Audit yyyymmdd (DAY1)
A1: Day | B1: From | C1: Until | D1: Duration | E1: Location | F1: Subject/Process | G1: ISO27001 Reference | H1: Standard | I1: Unit/Department | J1: Participants (Add person names) | K1: Auditors | L1: Remote (Yes/No)
A2: 1 | B2: 0.35416667 | C2: 0.375 | E2: HQ | F2: Arrival of auditors | H2: ISO 27001:2013 | K2: Lead Auditor name
A3: 1 | B3: =C2 -> 0.375 | C3: 0.38541667 | D3: =C3-B3 -> 0.010416667 | E3: HQ | F3: Opening meeting | H3: ISO 27001:2013 | I3: All audit participants | J3: All audit participants | K3: Lead Auditor name
A4: 1 | B4: =C3 -> 0.38541667 | C4: 0.40625 | D4: =C4-B4 -> 0.020833333 | E4: HQ | F4: Tour of the premises & Management | G4: A.11 | H4: ISO 27001:2013 | I4: Physical Security | J4: TBC | K4: Lead Auditor name
A5: 1 | B5: =C4 -> 0.40625 | C5: 0.5 | D5: =C5-B5 -> 0.09375 | E5: HQ | F5: Management | G5: 4.1; 4.2; 4.3; 4.4; 5.1; 5.2; 5.3; 6.1; 6.2; 9.2; 9.3; 10.1; 10.2; A.5.1; A.6.1; A.6.2; 6.3 | H5: ISO 27001:2013 | I5: Management | J5: TBC | K5: Lead Auditor name
A6: 1 | B6: =C5 -> 0.5 | C6: 0.54166667 | D6: =C6-B6 -> 0.041666667 | E6: HQ | F6: HR & Office management | G6: 7.1; 8.1; A.7.1; A.7.2; A.7.3 | H6: ISO 27001:2013 | I6: HR & Office management | J6: TBC | K6: Lead Auditor name
A7: 1 | B7: =C6 -> 0.54166667 | C7: 0.5625 | E7: HQ | F7: Break | H7: ISO 27001:2013 | J7: TBC | K7: Lead Auditor name
A8: 1 | B8: =C7 -> 0.5625 | C8: 0.60416667 | D8: =C8-B8 -> 0.041666667 | E8: HQ | F8: Finance, Legal & Contract Management | G8: A.15.1; A.15.2; A.18.1; A.18.2; A15.1 | H8: ISO 27001:2013 | I8: Finance & Legal | J8: TBC | K8: Lead Auditor name
A9: 1 | B9: =C8 -> 0.60416667 | C9: 0.70833333 | D9: =C9-B9 -> 0.10416667 | E9: HQ | F9: IT Operations and support | G9: 7.4; 7.5; 8.1; 8.2; 8.3; 9.1; A.8.1; A.8.2; A.8.3; A.9.1; A.9.2; A.9.3; A.9.4; A.12.1; A.12.2; A.12.3; A.12.4; A.12.5; A.12.6; A.12.7; A.13.1; A.13.2; A.16.1; A.17.1; A.17.2 | H9: ISO 27001:2013 | I9: Development Management | J9: TBC | K9: Lead Auditor name
A10: 1 | B10: =C9 -> 0.70833333 | C10: 0.72916667 | D10: =C10-B10 -> 0.020833333 | E10: HQ | F10: Summary of the day | H10: ISO 27001:2013 | I10: Management | J10: TBC | K10: Lead Auditor name
A11: 1 | B11: =C10 -> 0.72916667 | C11: 0.72916667 | D11: End of day 1 | E11: HQ | F11: End of day 1 | K11: Lead Auditor name
D12: =SUM(Table1[Duration]) -> 0.33333333

Sheet Interne Audit yyyymmdd (DAY2)
A1: Day | B1: From | C1: Until | D1: Duration | E1: Location | F1: Subject/Process | G1: ISO27001 Reference | H1: Standard | I1: Unit/Department | J1: Participants | K1: Auditors | L1: Remote (Y/N)
A2: 1 | B2: 0.35416667 | C2: 0.375 | E2: HQ | F2: Arrival of auditors | H2: ISO 27001:2013 | K2: Lead/co-auditor name
A3: 1 | B3: =C2 -> 0.375 | C3: 0.41666667 | D3: =C3-B3 -> 0.041666667 | E3: HQ | F3: ISMS Project | H3: ISO 27001:2013 | I3: Security officer / ISMS Project | J3: TBC | K3: Lead/co-auditor name
A4: 1 | B4: =C3 -> 0.41666667 | C4: 0.45833333 | D4: =C4-B4 -> 0.041666667 | E4: HQ | F4: Sales | G4: A.11 | H4: ISO 27001:2013 | I4: Sales | K4: Lead/co-auditor name
A5: 1 | B5: =C4 -> 0.45833333 | C5: 0.5 | D5: =C5-B5 -> 0.041666667 | E5: HQ | F5: Marketing | G5: 4.1; 4.2; 4.3; 4.4; 5.1; 5.2; 5.3; 6.1; 6.2; 9.2; 9.3; 10.1; 10.2; A.5.1; A.6.1; A.6.2; 6.3 | H5: ISO 27001:2013 | I5: Marketing | J5: TBC | K5: Lead/co-auditor name
A6: 1 | B6: =C5 -> 0.5 | C6: 0.54166667 | D6: =C6-B6 -> 0.041666667 | E6: HQ | F6: Product | G6: 7.1; 8.1; A.7.1; A.7.2; A.7.3 | H6: ISO 27001:2013 | I6: Product | J6: TBC | K6: Lead/co-auditor name
A7: 1 | B7: =C6 -> 0.54166667 | C7: 0.5625 | E7: HQ | F7: Break | H7: ISO 27001:2013 | J7: TBC | K7: Lead/co-auditor name
A8: 1 | B8: =C7 -> 0.5625 | C8: 0.60416667 | D8: =C8-B8 -> 0.041666667 | E8: HQ | F8: Quality & Regulatory | G8: A.18.1; A.18.2; | H8: ISO 27001:2013 | I8: Quality & Regulatory | J8: TBC | K8: Lead/co-auditor name
A9: 1 | B9: =C8 -> 0.60416667 | C9: 0.625 | D9: =C9-B9 -> 0.020833333 | E9: HQ | F9: Customer Service Delivery | H9: ISO 27001:2013 | I9: Customer Service Delivery | J9: TBC | K9: Lead/co-auditor name
B10: =C9 -> 0.625 | C10: 0.64583333 | D10: =C10-B10 -> 0.020833333 | E10: HQ | F10: Customer Service Support | I10: Customer Service Support | K10: Lead/co-auditor name
A11: 1 | B11: =C10 -> 0.64583333 | C11: 0.6875 | D11: =C11-B11 -> 0.041666667 | E11: HQ | F11: Preparation of closing meeting | H11: ISO 27001:2013 | I11: Auditor | J11: TBC | K11: Lead/co-auditor name
A12: 1 | B12: =C11 -> 0.6875 | C12: 0.72916667 | D12: =C12-B12 -> 0.041666667 | E12: HQ | F12: Closing meeting | I12: All audit participants | K12: Lead/co-auditor name
D13: =SUM(Table14[Duration]) -> 0.33333333

Sheet Audit Cycle plan
B1: 1 | C1: 0.33 | D1: 0.33 | E1: 0.66
A2: Departments | B2: Initial Audit (Y0) | C2: Surveillance 1 (Y0+1) | D2: Surveillance 2 (Y0+2) | E2: Recert (Y0+3))
A3: Management | B3: X | C3: X | D3: X | E3: X
A4: Physical Security | B4: X | C4: X | D4: X | E4: X
A5: Security officer / ISMS Project | B5: X | C5: X | D5: X | E5: X
A6: IT | B6: X | C6: X | E6: X
A7: Finance & Legal | B7: X | D7: X | E7: X
A8: HR & Office management | B8: X | D8: X | E8: X
A9: Sales | B9: X | C9: X | E9: X
A10: Sales - Customer Succes | B10: X | D10: X | E10: X
A11: Marketing | B11: X | D11: X | E11: X
A12: Development | B12: X | C12: X | E12: X
A13: Product | B13: X | C13: X | E13: X
A14: Quality & Regulatory | B14: X | C14: X | E14: X
A15: Customer Service Delivery | B15: X | D15: X | E15: X
A16: Customer Service Support | B16: X | D16: X | E16: X
B17: =COUNTA(B4:B16) -> 13 | C17: =COUNTA(C4:C16) -> 7 | D17: =COUNTA(D4:D16) -> 8 | E17: =COUNTA(E4:E16) -> 13

Sheet Lists
A1: Remote | B1: Auditor
A2: Yes | B2: Lead Auditor name
A3: No | B3: Co-auditor name 1
B4: Co-auditor name 2
